Workbook

Sheet RECETTES
B2: TABLEAU DETAILLE DES RECETTES
E4: COLLECTIVITE : …..........
B6: RECETTES DE FONCTIONNEMENT
B7: COMPTE | E7: INTITULES | F7: BUDGET PRIMITIF | G7: BUDGET ADDITIONNEL | H7: MODIFICATIONS +/- | I7: PREVISIONS DEFINITIVES (1) | J7: OR ADMIS (2) | K7: RECOUVREMENT | L7: RESTE A RECOUVRER | M7: TAUX D'EXECUTION (2)/(1)
B8: 70 | E8: IMPOTS SUR LES REVENUS, BENEFICES ET GAINS | F8: =SUM(F9) -> 0 | G8: =SUM(G9) -> 0 | H8: =SUM(H9) -> 0 | I8: =SUM(I9) -> 0 | J8: =SUM(J9) -> 0 | K8: =SUM(K9) -> 0 | L8: =SUM(L9) -> 0 | M8: =J8/I8 -> #DIV/0!
C9: 708 | E9: Autres impôts sur les revenus | F9: =SUM(F10) -> 0 | G9: =SUM(G10) -> 0 | H9: =SUM(H10) -> 0 | I9: =SUM(I10) -> 0 | J9: =SUM(J10) -> 0 | K9: =SUM(K10) -> 0 | L9: =J9-K9 -> 0
D10: 7080 | E10: Autres impôts sur les revenus - Impôt synthétique | L10: =J10-K10 -> 0 | M10: =J10/I10 -> #DIV/0!
B11: 71 | E11: IMPOTS SUR LE PATRIMOINE | F11: =SUM(F12,F14,F17) -> 0 | G11: =SUM(G12,G14,G17) -> 0 | H11: =SUM(H12,H14,H17) -> 0 | I11: =SUM(I12,I14,I17) -> 0 | J11: =SUM(J12,J14,J17) -> 0 | K11: =SUM(K12,K14,K17) -> 0 | L11: =SUM(L12,L14,L17) -> 0 | M11: =J11/I11 -> #DIV/0!
C12: 714 | E12: Impôts fonciers sur les terrains - IFT | F12: =SUM(F13) -> 0 | G12: =SUM(G13) -> 0 | H12: =SUM(H13) -> 0 | I12: =SUM(I13) -> 0 | J12: =SUM(J13) -> 0 | K12: =SUM(K13) -> 0 | L12: =J12-K12 -> 0
D13: 7140 | E13: Impôts fonciers sur les terrains - IFT | L13: =J13-K13 -> 0 | M13: =J13/I13 -> #DIV/0!
C14: 715 | E14: Impôt foncier sur les propriétés bâties – IFPB | F14: =SUM(F15:F16) -> 0 | G14: =SUM(G15:G16) -> 0 | H14: =SUM(H15:H16) -> 0 | I14: =SUM(I15:I16) -> 0 | J14: =SUM(J15:J16) -> 0 | K14: =SUM(K15:K16) -> 0 | L14: =J14-K14 -> 0
D15: 7151 | E15: Impôt foncier sur les propriétés bâties – IFPB | L15: =J15-K15 -> 0 | M15: =J15/I15 -> #DIV/0!
D16: 7158 | E16: Autres impôts locaux sur les propriétés baties | L16: =J16-K16 -> 0 | M16: =J16/I16 -> #DIV/0!
C17: 718 | E17: Taxe annuelle sur autres patrimoines | F17: =SUM(F18:F20) -> 0 | G17: =SUM(G18:G20) -> 0 | H17: =SUM(H18:H20) -> 0 | I17: =SUM(I18:I20) -> 0 | J17: =SUM(J18:J20) -> 0 | K17: =SUM(K18:K20) -> 0 | L17: =J17-K17 -> 0
D18: 7181 | E18: Taxes sur les appareils automatiques ou électroniques | L18: =J18-K18 -> 0 | M18: =J18/I18 -> #DIV/0!
D19: 7182 | E19: Taxes sur les appareils mecaniques | L19: =J19-K19 -> 0 | M19: =J19/I19 -> #DIV/0!
D20: 7188 | E20: Autres taxes et impots annuels | L20: =J20-K20 -> 0 | M20: =J20/I20 -> #DIV/0!
B21: 72 | E21: IMPOTS SUR LES BIENS ET SERVICES | F21: =SUM(F22,F28,F33,F39) -> 0 | G21: =SUM(G22,G28,G33,G39) -> 0 | H21: =SUM(H22,H28,H33,H39) -> 0 | I21: =SUM(I22,I28,I33,I39) -> 0 | J21: =SUM(J22,J28,J33,J39) -> 0 | K21: =SUM(K22,K28,K33,K39) -> 0 | L21: =SUM(L22,L28,L33,L39) -> 0 | M21: =J21/I21 -> #DIV/0!
C22: 725 | E22: Taxes particulières sur les biens | F22: =SUM(F23:F27) -> 0 | G22: =SUM(G23:G27) -> 0 | H22: =SUM(H23:H27) -> 0 | I22: =SUM(I23:I27) -> 0 | J22: =SUM(J23:J27) -> 0 | K22: =SUM(K23:K27) -> 0 | L22: =J22-K22 -> 0
D23: 7251 | E23: Taxes sur l'électricité | L23: =J23-K23 -> 0 | M23: =J23/I23 -> #DIV/0!
D24: 7252 | E24: Taxes sur l'eau | L24: =J24-K24 -> 0 | M24: =J24/I24 -> #DIV/0!
D25: 7253 | E25: Surtaxe sur l'eau et l'électricité | L25: =J25-K25 -> 0 | M25: =J25/I25 -> #DIV/0!
D26: 7254 | E26: Taxes sur les eaux minérales | L26: =J26-K26 -> 0 | M26: =J26/I26 -> #DIV/0!
D27: 7258 | E27: Autres taxes particulières sur les biens | L27: =J27-K27 -> 0 | M27: =J27/I27 -> #DIV/0!
C28: 726 | E28: Taxes particulières sur les services | F28: =SUM(F29:F32) -> 0 | G28: =SUM(G29:G32) -> 0 | H28: =SUM(H29:H32) -> 0 | I28: =SUM(I29:I32) -> 0 | J28: =SUM(J29:J32) -> 0 | K28: =SUM(K29:K32) -> 0 | L28: =J28-K28 -> 0
D29: 7261 | E29: taxes sur la publicité | L29: =J29-K29 -> 0 | M29: =J29/I29 -> #DIV/0!
D30: 7262 | E30: Taxe d’abattage | L30: =J30-K30 -> 0 | M30: =J30/I30 -> #DIV/0!
D31: 7263 | E31: Taxe de visite et de poinçonnage des viandes | L31: =J31-K31 -> 0 | M31: =J31/I31 -> #DIV/0!
D32: 7268 | E32: Autres taxes locales sur les services | L32: =J32-K32 -> 0 | M32: =J32/I32 -> #DIV/0!
C33: 727 | E33: Taxes particulières sur les activités | F33: =SUM(F34:F38) -> 0 | G33: =SUM(G34:G38) -> 0 | H33: =SUM(H34:H38) -> 0 | I33: =SUM(I34:I38) -> 0 | J33: =SUM(J34:J38) -> 0 | K33: =SUM(K34:K38) -> 0 | L33: =J33-K33 -> 0
D34: 7273 | E34: Impôt de licence | L34: =J34-K34 -> 0 | M34: =J34/I34 -> #DIV/0!
D35: 7274 | E35: Prélèvement sur les produits de jeux - PPJ | L35: =J35-K35 -> 0 | M35: =J35/I35 -> #DIV/0!
D36: 7276 | E36: Taxes sur les fêtes, spectacles et manifestations… | L36: =J36-K36 -> 0 | M36: =J36/I36 -> #DIV/0!
D37: 7277 | E37: Taxes sur les établissements exerçant des activités à but lucratif | L37: =J37-K37 -> 0 | M37: =J37/I37 -> #DIV/0!
D38: 7278 | E38: Autres taxes locales sur les activités | L38: =J38-K38 -> 0 | M38: =J38/I38 -> #DIV/0!
C39: 728 | E39: Autres impôts sur les biens et services | F39: =SUM(F40) -> 0 | G39: =SUM(G40) -> 0 | H39: =SUM(H40) -> 0 | I39: =SUM(I40) -> 0 | J39: =SUM(J40) -> 0 | K39: =SUM(K40) -> 0 | L39: =J39-K39 -> 0
D40: 7280 | E40: Autres impôts sur les biens et services | L40: =J40-K40 -> 0 | M40: =J40/I40 -> #DIV/0!
B41: 74 | E41: AUTRES RECETTES FISCALES | F41: =SUM(F42,F46) -> 0 | G41: =SUM(G42,G46) -> 0 | H41: =SUM(H42,H46) -> 0 | I41: =SUM(I42,I46) -> 0 | J41: =SUM(J42,J46) -> 0 | K41: =SUM(K42,K46) -> 0 | L41: =SUM(L42,L46) -> 0 | M41: =J41/I41 -> #DIV/0!
C42: 743 | E42: Amendes fiscales et pénalités | F42: =SUM(F43:F45) -> 0 | G42: =SUM(G43:G45) -> 0 | H42: =SUM(H43:H45) -> 0 | I42: =SUM(I43:I45) -> 0 | J42: =SUM(J43:J45) -> 0 | K42: =SUM(K43:K45) -> 0 | L42: =J42-K42 -> 0
D43: 7431 | E43: Amendes fiscales | L43: =J43-K43 -> 0 | M43: =J43/I43 -> #DIV/0!
...

Sheet RECAPITULATIF RECETTES
B2: RECAPITULATIF DES RECETTES
E4: COLLECTIVITE : …..........
B6: RECETTES DE FONCTIONNEMENT
B7: COMPTE | E7: INTITULES | F7: PREVISIONS DEFINITIVES | G7: OR ADMIS | H7: RECOUVREMENT | I7: RESTE A RECOUVRER
B8: 70 | E8: IMPOTS SUR LES REVENUS, BENEFICES ET GAINS | F8: =RECETTES!I8 -> 0 | G8: =RECETTES!J8 -> 0 | H8: =RECETTES!K8 -> 0 | I8: =RECETTES!L8 -> 0
B9: 71 | E9: IMPOTS SUR LE PATRIMOINE | F9: =RECETTES!I11 -> 0 | G9: =RECETTES!J11 -> 0 | H9: =RECETTES!K11 -> 0 | I9: =RECETTES!L11 -> 0
B10: 72 | E10: IMPOTS SUR LES BIENS ET SERVICES | F10: =RECETTES!I21 -> 0 | G10: =RECETTES!J21 -> 0 | H10: =RECETTES!K21 -> 0 | I10: =RECETTES!L21 -> 0
B11: 74 | E11: AUTRES RECETTES FISCALES | F11: =RECETTES!I41 -> 0 | G11: =RECETTES!J41 -> 0 | H11: =RECETTES!K41 -> 0 | I11: =RECETTES!L41 -> 0
B12: 75 | E12: CONTRIBUTIONS RECUES DES TIERS | F12: =RECETTES!I48 -> 0 | G12: =RECETTES!J48 -> 0 | H12: =RECETTES!K48 -> 0 | I12: =RECETTES!L48 -> 0
B13: 76 | E13: PRODUITS FINANCIERS | F13: =RECETTES!I61 -> 0 | G13: =RECETTES!J61 -> 0 | H13: =RECETTES!K61 -> 0 | I13: =RECETTES!L61 -> 0
B14: 77 | E14: RECETTES NON FISCALES | F14: =RECETTES!I74 -> 0 | G14: =RECETTES!J74 -> 0 | H14: =RECETTES!K74 -> 0 | I14: =RECETTES!L74 -> 0
E15: TOTAL RECETTES REELLES DE FONCTIONNEMENT | F15: =F8+F9+F10+F11+F12+F13+F14 -> 0 | G15: =G8+G9+G10+G11+G12+G13+G14 -> 0 | H15: =H8+H9+H10+H11+H12+H13+H14 -> 0 | I15: =I8+I9+I10+I11+I12+I13+I14 -> 0
E16: TOTAL RECETTES D'ORDRE FONCTIONNEMENT | F16: =RECETTES!I104 -> 0 | G16: =RECETTES!J104 -> 0 | H16: =RECETTES!K104 -> 0 | I16: =RECETTES!L104 -> 0
E17: SOUS-TOTAL FONCTIONNEMENT | F17: =F15+F16 -> 0 | G17: =G15+G16 -> 0 | H17: =H15+H16 -> 0 | I17: =I15+I16 -> 0
B19: RECETTE D'INVESTISSEMENT
B20: COMPTE | E20: INTITULE | F20: PREVISIONS DEFINITIVES | G20: OR ADMIS | H20: RECOUVREMENT | I20: RESTE A RECOUVRER
B21: 10 | E21: FONDS, DOTATIONS ET RESERVES | F21: =RECETTES!I109 -> 0 | G21: =RECETTES!J109 -> 0 | H21: =RECETTES!K109 -> 0 | I21: =RECETTES!L109 -> 0
B22: 13 | E22: SUBVENTIONS D'EQUIPEMENT | F22: =RECETTES!I123 -> 0 | G22: =RECETTES!J123 -> 0 | H22: =RECETTES!K123 -> 0 | I22: =RECETTES!L123 -> 0
B23: 14 | E23: CESSIONS D'IMMOBILISATIONS | F23: =RECETTES!I133 -> 0 | G23: =RECETTES!J133 -> 0 | H23: =RECETTES!K133 -> 0 | I23: =RECETTES!L133 -> 0
B24: 16 | E24: EMPRUNTS ET DETTES ASSIMILEES | F24: =RECETTES!I152 -> 0 | G24: =RECETTES!J152 -> 0 | H24: =RECETTES!K152 -> 0 | I24: =RECETTES!L152 -> 0
E25: TOTAL RECETTES REELLES INVESTISSEMENT | F25: =F21+F22+F23+F24 -> 0 | G25: =G21+G22+G23+G24 -> 0 | H25: =H21+H22+H23+H24 -> 0 | I25: =I21+I22+I23+I24 -> 0
B26: 10 | E26: FONDS, DOTATIONS ET RESERVES | F26: =RECETTES!I167 -> 0 | G26: =RECETTES!J167 -> 0 | H26: =RECETTES!K167 -> 0 | I26: =RECETTES!L167 -> 0
E27: RECETTE D'ORDRE INVESTISSEMENT | F27: =F26 -> 0 | G27: =G26 -> 0 | H27: =H26 -> 0 | I27: =I26 -> 0
E28: SOUS-TOTAL INVESTISSEMENT | F28: =F25+F27 -> 0 | G28: =G25+G27 -> 0 | H28: =H25+H27 -> 0 | I28: =I25+I27 -> 0

Sheet DEPENSES PROGRAMME I
B2: TABLEAU DETAILLE DES DEPENSES
E4: COLLECTIVITE : …..........
E6: PROGRAMME I :
B8: DEPENSES DE FONCTIONNEMENT
B9: COMPTE | E9: INTITULES | F9: BUDGET PRIMITIF | G9: BUDGET ADDITIONNEL | H9: MODIFICATIONS +/- | I9: PREVISIONS DEFINITIVES (1) | J9: ENGAGEMENT | K9: MANDAT ADMIS (2) | L9: PAIEMENT | M9: RESTE A PAYER | N9: TAUX D'EXECUTION (2)/(1)
B10: 60 | E10: CHARGES DE PERSONNEL | F10: =SUM(F11,F14,F17,F20,F23) -> 0 | G10: =SUM(G11,G14,G17,G20,G23) -> 0 | H10: =SUM(H11,H14,H17,H20,H23) -> 0 | I10: =SUM(I11,I14,I17,I20,I23) -> 0 | J10: =SUM(J11,J14,J17,J20,J23) -> 0 | K10: =SUM(K11,K14,K17,K20,K23) -> 0 | L10: =SUM(L11,L14,L17,L20,L23) -> 0 | M10: =SUM(M11,M14,M17,M20,M23) -> 0 | N10: =K10/I10 -> #DIV/0!
C11: 601 | E11: Salaires et accessoires | F11: =SUM(F12:F13) -> 0 | G11: =SUM(G12:G13) -> 0 | H11: =SUM(H12:H13) -> 0 | I11: =SUM(I12:I13) -> 0 | J11: =SUM(J12:J13) -> 0 | K11: =SUM(K12:K13) -> 0 | L11: =SUM(L12:L13) -> 0 | M11: =K11-L11 -> 0
D12: 6011 | E12: Personnel permanent | M12: =K12-L12 -> 0 | N12: =K12/I12 -> #DIV/0!
D13: 6012 | E13: Personnel non permanent | M13: =K13-L13 -> 0 | N13: =K13/I13 -> #DIV/0!
C14: 602 | E14: Indemnités liées à la solde | F14: =SUM(F15:F16) -> 0 | G14: =SUM(G15:G16) -> 0 | H14: =SUM(H15:H16) -> 0 | I14: =SUM(I15:I16) -> 0 | J14: =SUM(J15:J16) -> 0 | K14: =SUM(K15:K16) -> 0 | L14: =SUM(L15:L16) -> 0 | M14: =K14-L14 -> 0
D15: 6021 | E15: Personnel permanent | M15: =K15-L15 -> 0 | N15: =K15/I15 -> #DIV/0!
D16: 6022 | E16: Personnel non permanent | M16: =K16-L16 -> 0 | N16: =K16/I16 -> #DIV/0!
C17: 603 | E17: Indemnités et avantages liés à la fonction | F17: =SUM(F18:F19) -> 0 | G17: =SUM(G18:G19) -> 0 | H17: =SUM(H18:H19) -> 0 | I17: =SUM(I18:I19) -> 0 | J17: =SUM(J18:J19) -> 0 | K17: =SUM(K18:K19) -> 0 | L17: =SUM(L18:L19) -> 0 | M17: =K17-L17 -> 0
D18: 6031 | E18: Personnel permanent | M18: =K18-L18 -> 0 | N18: =K18/I18 -> #DIV/0!
D19: 6032 | E19: Personnel non permanent | M19: =K19-L19 -> 0 | N19: =K19/I19 -> #DIV/0!
C20: 604 | E20: Supplément familial de traitement | F20: =SUM(F21:F22) -> 0 | G20: =SUM(G21:G22) -> 0 | H20: =SUM(H21:H22) -> 0 | I20: =SUM(I21:I22) -> 0 | J20: =SUM(J21:J22) -> 0 | K20: =SUM(K21:K22) -> 0 | L20: =SUM(L21:L22) -> 0 | M20: =K20-L20 -> 0
D21: 6041 | E21: Personnel permanent | M21: =K21-L21 -> 0 | N21: =K21/I21 -> #DIV/0!
D22: 6042 | E22: Personnel non permanent | M22: =K22-L22 -> 0 | N22: =K22/I22 -> #DIV/0!
C23: 606 | E23: Charges sociales patronales | F23: =SUM(F24:F28) -> 0 | G23: =SUM(G24:G28) -> 0 | H23: =SUM(H24:H28) -> 0 | I23: =SUM(I24:I28) -> 0 | J23: =SUM(J24:J28) -> 0 | K23: =SUM(K24:K28) -> 0 | L23: =SUM(L24:L28) -> 0 | M23: =K23-L23 -> 0
D24: 6061 | E24: Cotisations à la CNAPS | M24: =K24-L24 -> 0 | N24: =K24/I24 -> #DIV/0!
D25: 6062 | E25: Cotisations caisse de retraites civiles et militaires | M25: =K25-L25 -> 0 | N25: =K25/I25 -> #DIV/0!
D26: 6063 | E26: CPR | M26: =K26-L26 -> 0 | N26: =K26/I26 -> #DIV/0!
D27: 6064 | E27: Cotisations aux OSIE | M27: =K27-L27 -> 0 | N27: =K27/I27 -> #DIV/0!
D28: 6068 | E28: Autres charges sociales patronales | M28: =K28-L28 -> 0 | N28: =K28/I28 -> #DIV/0!
B29: 61 | E29: ACHATS DE BIENS | F29: =SUM(F30,F38,F47,F51,F56) -> 0 | G29: =SUM(G30,G38,G47,G51,G56) -> 0 | H29: =SUM(H30,H38,H47,H51,H56) -> 0 | I29: =SUM(I30,I38,I47,I51,I56) -> 0 | J29: =SUM(J30,J38,J47,J51,J56) -> 0 | K29: =SUM(K30,K38,K47,K51,K56) -> 0 | L29: =SUM(L30,L38,L47,L51,L56) -> 0 | M29: =SUM(M30,M38,M47,M51,M56) -> 0 | N29: =K29/I29 -> #DIV/0!
C30: 611 | E30: Achats de biens de fonctionnement général | F30: =SUM(F31:F37) -> 0 | G30: =SUM(G31:G37) -> 0 | H30: =SUM(H31:H37) -> 0 | I30: =SUM(I31:I37) -> 0 | J30: =SUM(J31:J37) -> 0 | K30: =SUM(K31:K37) -> 0 | L30: =SUM(L31:L37) -> 0 | M30: =K30-L30 -> 0
D31: 6111 | E31: Fournitures et articles de bureau | M31: =K31-L31 -> 0 | N31: =K31/I31 -> #DIV/0!
D32: 6112 | E32: Imprimés, cachets et docuements administratifs | M32: =K32-L32 -> 0 | N32: =K32/I32 -> #DIV/0!
D33: 6113 | E33: Consomptibles informatiques | M33: =K33-L33 -> 0 | N33: =K33/I33 -> #DIV/0!
D34: 6114 | E34: Produits, petits matériels et menues dépenses d'entretien | M34: =K34-L34 -> 0 | N34: =K34/I34 -> #DIV/0!
D35: 6115 | E35: Petits outillages et fournitures d'atelier | M35: =K35-L35 -> 0 | N35: =K35/I35 -> #DIV/0!
D36: 6116 | E36: Instruments spécialisés | M36: =K36-L36 -> 0 | N36: =K36/I36 -> #DIV/0!
D37: 6117 | E37: Habillement | M37: =K37-L37 -> 0 | N37: =K37/I37 -> #DIV/0!
C38: 612 | E38: Achats de biens à usage spécifique | F38: =SUM(F39:F46) -> 0 | G38: =SUM(G39:G46) -> 0 | H38: =SUM(H39:H46) -> 0 | I38: =SUM(I39:I46) -> 0 | J38: =SUM(J39:J46) -> 0 | K38: =SUM(K39:K46) -> 0 | L38: =SUM(L39:L46) -> 0 | M38: =K38-L38 -> 0
D39: 6121 | E39: Fornitures scolaires | M39: =K39-L39 -> 0 | N39: =K39/I39 -> #DIV/0!
D40: 6122 | E40: Consommables médicaux | M40: =K40-L40 -> 0 | N40: =K40/I40 -> #DIV/0!
D41: 6123 | E41: Produits pahrmaceutiques | M41: =K41-L41 -> 0 | N41: =K41/I41 -> #DIV/0!
D42: 6124 | E42: Produits vétérianaires | M42: =K42-L42 -> 0 | N42: =K42/I42 -> #DIV/0!
D43: 6125 | E43: Produits alimentaires | M43: =K43-L43 -> 0 | N43: =K43/I43 -> #DIV/0!
D44: 6126 | E44: Intrants agricoles | M44: =K44-L44 -> 0 | N44: =K44/I44 -> #DIV/0!
...

Sheet DEPENSES PROGRAMME II
B2: TABLEAU DETAILLE DES DEPENSES
E4: COLLECTIVITE : …..........
E6: PROGRAMME II :
B8: DEPENSES DE FONCTIONNEMENT
B9: COMPTE | E9: INTITULES | F9: BUDGET PRIMITIF | G9: BUDGET ADDITIONNEL | H9: MODIFICATIONS +/- | I9: PREVISIONS DEFINITIVES (1) | J9: ENGAGEMENT | K9: MANDAT ADMIS (2) | L9: PAIEMENT | M9: RESTE A PAYER | N9: TAUX D'EXECUTION (2)/(1)
B10: 60 | E10: CHARGES DE PERSONNEL | F10: =SUM(F11,F14,F17,F20,F23) -> 0 | G10: =SUM(G11,G14,G17,G20,G23) -> 0 | H10: =SUM(H11,H14,H17,H20,H23) -> 0 | I10: =SUM(I11,I14,I17,I20,I23) -> 0 | J10: =SUM(J11,J14,J17,J20,J23) -> 0 | K10: =SUM(K11,K14,K17,K20,K23) -> 0 | L10: =SUM(L11,L14,L17,L20,L23) -> 0 | M10: =SUM(M11,M14,M17,M20,M23) -> 0 | N10: =K10/I10 -> #DIV/0!
C11: 601 | E11: Salaires et accessoires | F11: =SUM(F12:F13) -> 0 | G11: =SUM(G12:G13) -> 0 | H11: =SUM(H12:H13) -> 0 | I11: =SUM(I12:I13) -> 0 | J11: =SUM(J12:J13) -> 0 | K11: =SUM(K12:K13) -> 0 | L11: =SUM(L12:L13) -> 0 | M11: =K11-L11 -> 0
D12: 6011 | E12: Personnel permanent | M12: =K12-L12 -> 0 | N12: =K12/I12 -> #DIV/0!
D13: 6012 | E13: Personnel non permanent | M13: =K13-L13 -> 0 | N13: =K13/I13 -> #DIV/0!
C14: 602 | E14: Indemnités liées à la solde | F14: =SUM(F15:F16) -> 0 | G14: =SUM(G15:G16) -> 0 | H14: =SUM(H15:H16) -> 0 | I14: =SUM(I15:I16) -> 0 | J14: =SUM(J15:J16) -> 0 | K14: =SUM(K15:K16) -> 0 | L14: =SUM(L15:L16) -> 0 | M14: =K14-L14 -> 0
D15: 6021 | E15: Personnel permanent | M15: =K15-L15 -> 0 | N15: =K15/I15 -> #DIV/0!
D16: 6022 | E16: Personnel non permanent | M16: =K16-L16 -> 0 | N16: =K16/I16 -> #DIV/0!
C17: 603 | E17: Indemnités et avantages liés à la fonction | F17: =SUM(F18:F19) -> 0 | G17: =SUM(G18:G19) -> 0 | H17: =SUM(H18:H19) -> 0 | I17: =SUM(I18:I19) -> 0 | J17: =SUM(J18:J19) -> 0 | K17: =SUM(K18:K19) -> 0 | L17: =SUM(L18:L19) -> 0 | M17: =K17-L17 -> 0
D18: 6031 | E18: Personnel permanent | M18: =K18-L18 -> 0 | N18: =K18/I18 -> #DIV/0!
D19: 6032 | E19: Personnel non permanent | M19: =K19-L19 -> 0 | N19: =K19/I19 -> #DIV/0!
C20: 604 | E20: Supplément familial de traitement | F20: =SUM(F21:F22) -> 0 | G20: =SUM(G21:G22) -> 0 | H20: =SUM(H21:H22) -> 0 | I20: =SUM(I21:I22) -> 0 | J20: =SUM(J21:J22) -> 0 | K20: =SUM(K21:K22) -> 0 | L20: =SUM(L21:L22) -> 0 | M20: =K20-L20 -> 0
D21: 6041 | E21: Personnel permanent | M21: =K21-L21 -> 0 | N21: =K21/I21 -> #DIV/0!
D22: 6042 | E22: Personnel non permanent | M22: =K22-L22 -> 0 | N22: =K22/I22 -> #DIV/0!
C23: 606 | E23: Charges sociales patronales | F23: =SUM(F24:F28) -> 0 | G23: =SUM(G24:G28) -> 0 | H23: =SUM(H24:H28) -> 0 | I23: =SUM(I24:I28) -> 0 | J23: =SUM(J24:J28) -> 0 | K23: =SUM(K24:K28) -> 0 | L23: =SUM(L24:L28) -> 0 | M23: =K23-L23 -> 0
D24: 6061 | E24: Cotisations à la CNAPS | M24: =K24-L24 -> 0 | N24: =K24/I24 -> #DIV/0!
D25: 6062 | E25: Cotisations caisse de retraites civiles et militaires | M25: =K25-L25 -> 0 | N25: =K25/I25 -> #DIV/0!
D26: 6063 | E26: CPR | M26: =K26-L26 -> 0 | N26: =K26/I26 -> #DIV/0!
D27: 6064 | E27: Cotisations aux OSIE | M27: =K27-L27 -> 0 | N27: =K27/I27 -> #DIV/0!
D28: 6068 | E28: Autres charges sociales patronales | M28: =K28-L28 -> 0 | N28: =K28/I28 -> #DIV/0!
B29: 61 | E29: ACHATS DE BIENS | F29: =SUM(F30,F38,F47,F51,F56) -> 0 | G29: =SUM(G30,G38,G47,G51,G56) -> 0 | H29: =SUM(H30,H38,H47,H51,H56) -> 0 | I29: =SUM(I30,I38,I47,I51,I56) -> 0 | J29: =SUM(J30,J38,J47,J51,J56) -> 0 | K29: =SUM(K30,K38,K47,K51,K56) -> 0 | L29: =SUM(L30,L38,L47,L51,L56) -> 0 | M29: =SUM(M30,M38,M47,M51,M56) -> 0 | N29: =K29/I29 -> #DIV/0!
C30: 611 | E30: Achats de biens de fonctionnement général | F30: =SUM(F31:F37) -> 0 | G30: =SUM(G31:G37) -> 0 | H30: =SUM(H31:H37) -> 0 | I30: =SUM(I31:I37) -> 0 | J30: =SUM(J31:J37) -> 0 | K30: =SUM(K31:K37) -> 0 | L30: =SUM(L31:L37) -> 0 | M30: =K30-L30 -> 0
D31: 6111 | E31: Fournitures et articles de bureau | M31: =K31-L31 -> 0 | N31: =K31/I31 -> #DIV/0!
D32: 6112 | E32: Imprimés, cachets et docuements administratifs | M32: =K32-L32 -> 0 | N32: =K32/I32 -> #DIV/0!
D33: 6113 | E33: Consomptibles informatiques | M33: =K33-L33 -> 0 | N33: =K33/I33 -> #DIV/0!
D34: 6114 | E34: Produits, petits matériels et menues dépenses d'entretien | M34: =K34-L34 -> 0 | N34: =K34/I34 -> #DIV/0!
D35: 6115 | E35: Petits outillages et fournitures d'atelier | M35: =K35-L35 -> 0 | N35: =K35/I35 -> #DIV/0!
D36: 6116 | E36: Instruments spécialisés | M36: =K36-L36 -> 0 | N36: =K36/I36 -> #DIV/0!
D37: 6117 | E37: Habillement | M37: =K37-L37 -> 0 | N37: =K37/I37 -> #DIV/0!
C38: 612 | E38: Achats de biens à usage spécifique | F38: =SUM(F39:F46) -> 0 | G38: =SUM(G39:G46) -> 0 | H38: =SUM(H39:H46) -> 0 | I38: =SUM(I39:I46) -> 0 | J38: =SUM(J39:J46) -> 0 | K38: =SUM(K39:K46) -> 0 | L38: =SUM(L39:L46) -> 0 | M38: =K38-L38 -> 0
D39: 6121 | E39: Fornitures scolaires | M39: =K39-L39 -> 0 | N39: =K39/I39 -> #DIV/0!
D40: 6122 | E40: Consommables médicaux | M40: =K40-L40 -> 0 | N40: =K40/I40 -> #DIV/0!
D41: 6123 | E41: Produits pahrmaceutiques | M41: =K41-L41 -> 0 | N41: =K41/I41 -> #DIV/0!
D42: 6124 | E42: Produits vétérianaires | M42: =K42-L42 -> 0 | N42: =K42/I42 -> #DIV/0!
D43: 6125 | E43: Produits alimentaires | M43: =K43-L43 -> 0 | N43: =K43/I43 -> #DIV/0!
D44: 6126 | E44: Intrants agricoles | M44: =K44-L44 -> 0 | N44: =K44/I44 -> #DIV/0!
...

Sheet DEPENSES PROGRAMME III
B2: TABLEAU DETAILLE DES DEPENSES
E4: COLLECTIVITE : …..........
E6: PROGRAMME III :
B8: DEPENSES DE FONCTIONNEMENT
B9: COMPTE | E9: INTITULES | F9: BUDGET PRIMITIF | G9: BUDGET ADDITIONNEL | H9: MODIFICATIONS +/- | I9: PREVISIONS DEFINITIVES (1) | J9: ENGAGEMENT | K9: MANDAT ADMIS (2) | L9: PAIEMENT | M9: RESTE A PAYER | N9: TAUX D'EXECUTION (2)/(1)
B10: 60 | E10: CHARGES DE PERSONNEL | F10: =SUM(F11,F14,F17,F20,F23) -> 0 | G10: =SUM(G11,G14,G17,G20,G23) -> 0 | H10: =SUM(H11,H14,H17,H20,H23) -> 0 | I10: =SUM(I11,I14,I17,I20,I23) -> 0 | J10: =SUM(J11,J14,J17,J20,J23) -> 0 | K10: =SUM(K11,K14,K17,K20,K23) -> 0 | L10: =SUM(L11,L14,L17,L20,L23) -> 0 | M10: =SUM(M11,M14,M17,M20,M23) -> 0 | N10: =K10/I10 -> #DIV/0!
C11: 601 | E11: Salaires et accessoires | F11: =SUM(F12:F13) -> 0 | G11: =SUM(G12:G13) -> 0 | H11: =SUM(H12:H13) -> 0 | I11: =SUM(I12:I13) -> 0 | J11: =SUM(J12:J13) -> 0 | K11: =SUM(K12:K13) -> 0 | L11: =SUM(L12:L13) -> 0 | M11: =K11-L11 -> 0
D12: 6011 | E12: Personnel permanent | M12: =K12-L12 -> 0 | N12: =K12/I12 -> #DIV/0!
D13: 6012 | E13: Personnel non permanent | M13: =K13-L13 -> 0 | N13: =K13/I13 -> #DIV/0!
C14: 602 | E14: Indemnités liées à la solde | F14: =SUM(F15:F16) -> 0 | G14: =SUM(G15:G16) -> 0 | H14: =SUM(H15:H16) -> 0 | I14: =SUM(I15:I16) -> 0 | J14: =SUM(J15:J16) -> 0 | K14: =SUM(K15:K16) -> 0 | L14: =SUM(L15:L16) -> 0 | M14: =K14-L14 -> 0
D15: 6021 | E15: Personnel permanent | M15: =K15-L15 -> 0 | N15: =K15/I15 -> #DIV/0!
D16: 6022 | E16: Personnel non permanent | M16: =K16-L16 -> 0 | N16: =K16/I16 -> #DIV/0!
C17: 603 | E17: Indemnités et avantages liés à la fonction | F17: =SUM(F18:F19) -> 0 | G17: =SUM(G18:G19) -> 0 | H17: =SUM(H18:H19) -> 0 | I17: =SUM(I18:I19) -> 0 | J17: =SUM(J18:J19) -> 0 | K17: =SUM(K18:K19) -> 0 | L17: =SUM(L18:L19) -> 0 | M17: =K17-L17 -> 0
D18: 6031 | E18: Personnel permanent | M18: =K18-L18 -> 0 | N18: =K18/I18 -> #DIV/0!
D19: 6032 | E19: Personnel non permanent | M19: =K19-L19 -> 0 | N19: =K19/I19 -> #DIV/0!
C20: 604 | E20: Supplément familial de traitement | F20: =SUM(F21:F22) -> 0 | G20: =SUM(G21:G22) -> 0 | H20: =SUM(H21:H22) -> 0 | I20: =SUM(I21:I22) -> 0 | J20: =SUM(J21:J22) -> 0 | K20: =SUM(K21:K22) -> 0 | L20: =SUM(L21:L22) -> 0 | M20: =K20-L20 -> 0
D21: 6041 | E21: Personnel permanent | M21: =K21-L21 -> 0 | N21: =K21/I21 -> #DIV/0!
D22: 6042 | E22: Personnel non permanent | M22: =K22-L22 -> 0 | N22: =K22/I22 -> #DIV/0!
C23: 606 | E23: Charges sociales patronales | F23: =SUM(F24:F28) -> 0 | G23: =SUM(G24:G28) -> 0 | H23: =SUM(H24:H28) -> 0 | I23: =SUM(I24:I28) -> 0 | J23: =SUM(J24:J28) -> 0 | K23: =SUM(K24:K28) -> 0 | L23: =SUM(L24:L28) -> 0 | M23: =K23-L23 -> 0
D24: 6061 | E24: Cotisations à la CNAPS | M24: =K24-L24 -> 0 | N24: =K24/I24 -> #DIV/0!
D25: 6062 | E25: Cotisations caisse de retraites civiles et militaires | M25: =K25-L25 -> 0 | N25: =K25/I25 -> #DIV/0!
D26: 6063 | E26: CPR | M26: =K26-L26 -> 0 | N26: =K26/I26 -> #DIV/0!
D27: 6064 | E27: Cotisations aux OSIE | M27: =K27-L27 -> 0 | N27: =K27/I27 -> #DIV/0!
D28: 6068 | E28: Autres charges sociales patronales | M28: =K28-L28 -> 0 | N28: =K28/I28 -> #DIV/0!
B29: 61 | E29: ACHATS DE BIENS | F29: =SUM(F30,F38,F47,F51,F56) -> 0 | G29: =SUM(G30,G38,G47,G51,G56) -> 0 | H29: =SUM(H30,H38,H47,H51,H56) -> 0 | I29: =SUM(I30,I38,I47,I51,I56) -> 0 | J29: =SUM(J30,J38,J47,J51,J56) -> 0 | K29: =SUM(K30,K38,K47,K51,K56) -> 0 | L29: =SUM(L30,L38,L47,L51,L56) -> 0 | M29: =SUM(M30,M38,M47,M51,M56) -> 0 | N29: =K29/I29 -> #DIV/0!
C30: 611 | E30: Achats de biens de fonctionnement général | F30: =SUM(F31:F37) -> 0 | G30: =SUM(G31:G37) -> 0 | H30: =SUM(H31:H37) -> 0 | I30: =SUM(I31:I37) -> 0 | J30: =SUM(J31:J37) -> 0 | K30: =SUM(K31:K37) -> 0 | L30: =SUM(L31:L37) -> 0 | M30: =K30-L30 -> 0
D31: 6111 | E31: Fournitures et articles de bureau | M31: =K31-L31 -> 0 | N31: =K31/I31 -> #DIV/0!
D32: 6112 | E32: Imprimés, cachets et docuements administratifs | M32: =K32-L32 -> 0 | N32: =K32/I32 -> #DIV/0!
D33: 6113 | E33: Consomptibles informatiques | M33: =K33-L33 -> 0 | N33: =K33/I33 -> #DIV/0!
D34: 6114 | E34: Produits, petits matériels et menues dépenses d'entretien | M34: =K34-L34 -> 0 | N34: =K34/I34 -> #DIV/0!
D35: 6115 | E35: Petits outillages et fournitures d'atelier | M35: =K35-L35 -> 0 | N35: =K35/I35 -> #DIV/0!
D36: 6116 | E36: Instruments spécialisés | M36: =K36-L36 -> 0 | N36: =K36/I36 -> #DIV/0!
D37: 6117 | E37: Habillement | M37: =K37-L37 -> 0 | N37: =K37/I37 -> #DIV/0!
C38: 612 | E38: Achats de biens à usage spécifique | F38: =SUM(F39:F46) -> 0 | G38: =SUM(G39:G46) -> 0 | H38: =SUM(H39:H46) -> 0 | I38: =SUM(I39:I46) -> 0 | J38: =SUM(J39:J46) -> 0 | K38: =SUM(K39:K46) -> 0 | L38: =SUM(L39:L46) -> 0 | M38: =K38-L38 -> 0
D39: 6121 | E39: Fornitures scolaires | M39: =K39-L39 -> 0 | N39: =K39/I39 -> #DIV/0!
D40: 6122 | E40: Consommables médicaux | M40: =K40-L40 -> 0 | N40: =K40/I40 -> #DIV/0!
D41: 6123 | E41: Produits pahrmaceutiques | M41: =K41-L41 -> 0 | N41: =K41/I41 -> #DIV/0!
D42: 6124 | E42: Produits vétérianaires | M42: =K42-L42 -> 0 | N42: =K42/I42 -> #DIV/0!
D43: 6125 | E43: Produits alimentaires | M43: =K43-L43 -> 0 | N43: =K43/I43 -> #DIV/0!
D44: 6126 | E44: Intrants agricoles | M44: =K44-L44 -> 0 | N44: =K44/I44 -> #DIV/0!
...

Sheet RECAP DEPENSES PAR PROGRAMME
B2: RECAPITULATIF DES DEPENSES PAR PROGRAMME
E4: COLLECTIVITE : …..........
B7: DEPENSES DE FONCTIONNEMENT
F8: MANDATEMENT | J8: PAIEMENT | N8: RESTE A PAYER
B9: COMPTE | E9: INTITULES | F9: PROGRAMME I | G9: PROGRAMME II | H9: PROGRAMME III | I9: TOTAL | J9: PROGRAMME I | K9: PROGRAMME II | L9: PROGRAMME III | M9: TOTAL | N9: PROGRAMME I | O9: PROGRAMME II | P9: PROGRAMME III | Q9: TOTAL
B10: 60 | E10: CHARGES DE PERSONNEL | F10: =SUM(F11,F14,F17,F20,F23) -> 0 | G10: =SUM(G11,G14,G17,G20,G23) -> 0 | H10: =SUM(H11,H14,H17,H20,H23) -> 0 | I10: =SUM(F10,G10,H10) -> 0 | J10: =SUM(J11,J14,J17,J20,J23) -> 0 | K10: =SUM(K11,K14,K17,K20,K23) -> 0 | L10: =SUM(L11,L14,L17,L20,L23) -> 0 | M10: =SUM(J10,K10,L10) -> 0 | N10: =SUM(N11,N14,N17,N20,N23) -> 0 | O10: =SUM(O11,O14,O17,O20,O23) -> 0 | P10: =SUM(P11,P14,P17,P20,P23) -> 0 | Q10: =SUM(N10,O10,P10) -> 0
C11: 601 | E11: Salaires et accessoires | F11: =SUM(F12:F13) -> 0 | G11: =SUM(G12:G13) -> 0 | H11: =SUM(H12:H13) -> 0 | J11: =SUM(J12:J13) -> 0 | K11: =SUM(K12:K13) -> 0 | L11: =SUM(L12:L13) -> 0 | N11: =SUM(N12:N13) -> 0 | O11: =SUM(O12:O13) -> 0 | P11: =SUM(P12:P13) -> 0
D12: 6011 | E12: Personnel permanent | F12: ='DEPENSES PROGRAMME I'!K12 -> 0 | G12: ='DEPENSES PROGRAMME II'!K12 -> 0 | H12: ='DEPENSES PROGRAMME III'!K12 -> 0 | J12: ='DEPENSES PROGRAMME I'!L12 -> 0 | K12: ='DEPENSES PROGRAMME II'!L12 -> 0 | L12: ='DEPENSES PROGRAMME III'!L12 -> 0 | N12: ='DEPENSES PROGRAMME I'!M12 -> 0 | O12: ='DEPENSES PROGRAMME II'!M12 -> 0 | P12: ='DEPENSES PROGRAMME III'!M12 -> 0
D13: 6012 | E13: Personnel non permanent | F13: ='DEPENSES PROGRAMME I'!K13 -> 0 | G13: ='DEPENSES PROGRAMME II'!K13 -> 0 | H13: ='DEPENSES PROGRAMME III'!K13 -> 0 | J13: ='DEPENSES PROGRAMME I'!L13 -> 0 | K13: ='DEPENSES PROGRAMME II'!L13 -> 0 | L13: ='DEPENSES PROGRAMME III'!L13 -> 0 | N13: ='DEPENSES PROGRAMME I'!M13 -> 0 | O13: ='DEPENSES PROGRAMME II'!M13 -> 0 | P13: ='DEPENSES PROGRAMME III'!M13 -> 0
C14: 602 | E14: Indemnités liées à la solde | F14: =SUM(F15:F16) -> 0 | G14: =SUM(G15:G16) -> 0 | H14: =SUM(H15:H16) -> 0 | J14: =SUM(J15:J16) -> 0 | K14: =SUM(K15:K16) -> 0 | L14: =SUM(L15:L16) -> 0 | N14: =SUM(N15:N16) -> 0 | O14: =SUM(O15:O16) -> 0 | P14: =SUM(P15:P16) -> 0
D15: 6021 | E15: Personnel permanent | F15: ='DEPENSES PROGRAMME I'!K15 -> 0 | G15: ='DEPENSES PROGRAMME II'!K15 -> 0 | H15: ='DEPENSES PROGRAMME III'!K15 -> 0 | J15: ='DEPENSES PROGRAMME I'!L15 -> 0 | K15: ='DEPENSES PROGRAMME II'!L15 -> 0 | L15: ='DEPENSES PROGRAMME III'!L15 -> 0 | N15: ='DEPENSES PROGRAMME I'!M15 -> 0 | O15: ='DEPENSES PROGRAMME II'!M15 -> 0 | P15: ='DEPENSES PROGRAMME III'!M15 -> 0
D16: 6022 | E16: Personnel non permanent | F16: ='DEPENSES PROGRAMME I'!K16 -> 0 | G16: ='DEPENSES PROGRAMME II'!K16 -> 0 | H16: ='DEPENSES PROGRAMME III'!K16 -> 0 | J16: ='DEPENSES PROGRAMME I'!L16 -> 0 | K16: ='DEPENSES PROGRAMME II'!L16 -> 0 | L16: ='DEPENSES PROGRAMME III'!L16 -> 0 | N16: ='DEPENSES PROGRAMME I'!M16 -> 0 | O16: ='DEPENSES PROGRAMME II'!M16 -> 0 | P16: ='DEPENSES PROGRAMME III'!M16 -> 0
C17: 603 | E17: Indemnités et avantages liés à la fonction | F17: =SUM(F18:F19) -> 0 | G17: =SUM(G18:G19) -> 0 | H17: =SUM(H18:H19) -> 0 | J17: =SUM(J18:J19) -> 0 | K17: =SUM(K18:K19) -> 0 | L17: =SUM(L18:L19) -> 0 | N17: =SUM(N18:N19) -> 0 | O17: =SUM(O18:O19) -> 0 | P17: =SUM(P18:P19) -> 0
D18: 6031 | E18: Personnel permanent | F18: ='DEPENSES PROGRAMME I'!K18 -> 0 | G18: ='DEPENSES PROGRAMME II'!K18 -> 0 | H18: ='DEPENSES PROGRAMME III'!K18 -> 0 | J18: ='DEPENSES PROGRAMME I'!L18 -> 0 | K18: ='DEPENSES PROGRAMME II'!L18 -> 0 | L18: ='DEPENSES PROGRAMME III'!L18 -> 0 | N18: ='DEPENSES PROGRAMME I'!M18 -> 0 | O18: ='DEPENSES PROGRAMME II'!M18 -> 0 | P18: ='DEPENSES PROGRAMME III'!M18 -> 0
D19: 6032 | E19: Personnel non permanent | F19: ='DEPENSES PROGRAMME I'!K19 -> 0 | G19: ='DEPENSES PROGRAMME II'!K19 -> 0 | H19: ='DEPENSES PROGRAMME III'!K19 -> 0 | J19: ='DEPENSES PROGRAMME I'!L19 -> 0 | K19: ='DEPENSES PROGRAMME II'!L19 -> 0 | L19: ='DEPENSES PROGRAMME III'!L19 -> 0 | N19: ='DEPENSES PROGRAMME I'!M19 -> 0 | O19: ='DEPENSES PROGRAMME II'!M19 -> 0 | P19: ='DEPENSES PROGRAMME III'!M19 -> 0
C20: 604 | E20: Supplément familial de traitement | F20: =SUM(F21:F22) -> 0 | G20: =SUM(G21:G22) -> 0 | H20: =SUM(H21:H22) -> 0 | J20: =SUM(J21:J22) -> 0 | K20: =SUM(K21:K22) -> 0 | L20: =SUM(L21:L22) -> 0 | N20: =SUM(N21:N22) -> 0 | O20: =SUM(O21:O22) -> 0 | P20: =SUM(P21:P22) -> 0
D21: 6041 | E21: Personnel permanent | F21: ='DEPENSES PROGRAMME I'!K21 -> 0 | G21: ='DEPENSES PROGRAMME II'!K21 -> 0 | H21: ='DEPENSES PROGRAMME III'!K21 -> 0 | J21: ='DEPENSES PROGRAMME I'!L21 -> 0 | K21: ='DEPENSES PROGRAMME II'!L21 -> 0 | L21: ='DEPENSES PROGRAMME III'!L21 -> 0 | N21: ='DEPENSES PROGRAMME I'!M21 -> 0 | O21: ='DEPENSES PROGRAMME II'!M21 -> 0 | P21: ='DEPENSES PROGRAMME III'!M21 -> 0
D22: 6042 | E22: Personnel non permanent | F22: ='DEPENSES PROGRAMME I'!K22 -> 0 | G22: ='DEPENSES PROGRAMME II'!K22 -> 0 | H22: ='DEPENSES PROGRAMME III'!K22 -> 0 | J22: ='DEPENSES PROGRAMME I'!L22 -> 0 | K22: ='DEPENSES PROGRAMME II'!L22 -> 0 | L22: ='DEPENSES PROGRAMME III'!L22 -> 0 | N22: ='DEPENSES PROGRAMME I'!M22 -> 0 | O22: ='DEPENSES PROGRAMME II'!M22 -> 0 | P22: ='DEPENSES PROGRAMME III'!M22 -> 0
C23: 606 | E23: Charges sociales patronales | F23: =SUM(F24:F28) -> 0 | G23: =SUM(G24:G28) -> 0 | H23: =SUM(H24:H28) -> 0 | J23: =SUM(J24:J28) -> 0 | K23: =SUM(K24:K28) -> 0 | L23: =SUM(L24:L28) -> 0 | N23: =SUM(N24:N28) -> 0 | O23: =SUM(O24:O28) -> 0 | P23: =SUM(P24:P28) -> 0
D24: 6061 | E24: Cotisations à la CNAPS | F24: ='DEPENSES PROGRAMME I'!K24 -> 0 | G24: ='DEPENSES PROGRAMME II'!K24 -> 0 | H24: ='DEPENSES PROGRAMME III'!K24 -> 0 | J24: ='DEPENSES PROGRAMME I'!L24 -> 0 | K24: ='DEPENSES PROGRAMME II'!L24 -> 0 | L24: ='DEPENSES PROGRAMME III'!L24 -> 0 | N24: ='DEPENSES PROGRAMME I'!M24 -> 0 | O24: ='DEPENSES PROGRAMME II'!M24 -> 0 | P24: ='DEPENSES PROGRAMME III'!M24 -> 0
D25: 6062 | E25: Cotisations caisse de retraites civiles et militaires | F25: ='DEPENSES PROGRAMME I'!K25 -> 0 | G25: ='DEPENSES PROGRAMME II'!K25 -> 0 | H25: ='DEPENSES PROGRAMME III'!K25 -> 0 | J25: ='DEPENSES PROGRAMME I'!L25 -> 0 | K25: ='DEPENSES PROGRAMME II'!L25 -> 0 | L25: ='DEPENSES PROGRAMME III'!L25 -> 0 | N25: ='DEPENSES PROGRAMME I'!M25 -> 0 | O25: ='DEPENSES PROGRAMME II'!M25 -> 0 | P25: ='DEPENSES PROGRAMME III'!M25 -> 0
D26: 6063 | E26: CPR | F26: ='DEPENSES PROGRAMME I'!K26 -> 0 | G26: ='DEPENSES PROGRAMME II'!K26 -> 0 | H26: ='DEPENSES PROGRAMME III'!K26 -> 0 | J26: ='DEPENSES PROGRAMME I'!L26 -> 0 | K26: ='DEPENSES PROGRAMME II'!L26 -> 0 | L26: ='DEPENSES PROGRAMME III'!L26 -> 0 | N26: ='DEPENSES PROGRAMME I'!M26 -> 0 | O26: ='DEPENSES PROGRAMME II'!M26 -> 0 | P26: ='DEPENSES PROGRAMME III'!M26 -> 0
D27: 6064 | E27: Cotisations aux OSIE | F27: ='DEPENSES PROGRAMME I'!K27 -> 0 | G27: ='DEPENSES PROGRAMME II'!K27 -> 0 | H27: ='DEPENSES PROGRAMME III'!K27 -> 0 | J27: ='DEPENSES PROGRAMME I'!L27 -> 0 | K27: ='DEPENSES PROGRAMME II'!L27 -> 0 | L27: ='DEPENSES PROGRAMME III'!L27 -> 0 | N27: ='DEPENSES PROGRAMME I'!M27 -> 0 | O27: ='DEPENSES PROGRAMME II'!M27 -> 0 | P27: ='DEPENSES PROGRAMME III'!M27 -> 0
D28: 6068 | E28: Autres charges sociales patronales | F28: ='DEPENSES PROGRAMME I'!K28 -> 0 | G28: ='DEPENSES PROGRAMME II'!K28 -> 0 | H28: ='DEPENSES PROGRAMME III'!K28 -> 0 | J28: ='DEPENSES PROGRAMME I'!L28 -> 0 | K28: ='DEPENSES PROGRAMME II'!L28 -> 0 | L28: ='DEPENSES PROGRAMME III'!L28 -> 0 | N28: ='DEPENSES PROGRAMME I'!M28 -> 0 | O28: ='DEPENSES PROGRAMME II'!M28 -> 0 | P28: ='DEPENSES PROGRAMME III'!M28 -> 0
B29: 61 | E29: ACHATS DE BIENS | F29: =SUM(F30,F38,F47,F51,F56) -> 0 | G29: =SUM(G30,G38,G47,G51,G56) -> 0 | H29: =SUM(H30,H38,H47,H51,H56) -> 0 | I29: =SUM(F29,G29,H29) -> 0 | J29: =SUM(J30,J38,J47,J51,J56) -> 0 | K29: =SUM(K30,K38,K47,K51,K56) -> 0 | L29: =SUM(L30,L38,L47,L51,L56) -> 0 | M29: =SUM(J29,K29,L29) -> 0 | N29: =SUM(N30,N38,N47,N51,N56) -> 0 | O29: =SUM(O30,O38,O47,O51,O56) -> 0 | P29: =SUM(P30,P38,P47,P51,P56) -> 0 | Q29: =SUM(N29,O29,P29) -> 0
C30: 611 | E30: Achats de biens de fonctionnement général | F30: =SUM(F31:F37) -> 0 | G30: =SUM(G31:G37) -> 0 | H30: =SUM(H31:H37) -> 0 | J30: =SUM(J31:J37) -> 0 | K30: =SUM(K31:K37) -> 0 | L30: =SUM(L31:L37) -> 0 | N30: =SUM(N31:N37) -> 0 | O30: =SUM(O31:O37) -> 0 | P30: =SUM(P31:P37) -> 0
D31: 6111 | E31: Fournitures et articles de bureau | F31: ='DEPENSES PROGRAMME I'!K31 -> 0 | G31: ='DEPENSES PROGRAMME II'!K31 -> 0 | H31: ='DEPENSES PROGRAMME III'!K31 -> 0 | J31: ='DEPENSES PROGRAMME I'!L31 -> 0 | K31: ='DEPENSES PROGRAMME II'!L31 -> 0 | L31: ='DEPENSES PROGRAMME III'!L31 -> 0 | N31: ='DEPENSES PROGRAMME I'!M31 -> 0 | O31: ='DEPENSES PROGRAMME II'!M31 -> 0 | P31: ='DEPENSES PROGRAMME III'!M31 -> 0
D32: 6112 | E32: Imprimés, cachets et docuements administratifs | F32: ='DEPENSES PROGRAMME I'!K32 -> 0 | G32: ='DEPENSES PROGRAMME II'!K32 -> 0 | H32: ='DEPENSES PROGRAMME III'!K32 -> 0 | J32: ='DEPENSES PROGRAMME I'!L32 -> 0 | K32: ='DEPENSES PROGRAMME II'!L32 -> 0 | L32: ='DEPENSES PROGRAMME III'!L32 -> 0 | N32: ='DEPENSES PROGRAMME I'!M32 -> 0 | O32: ='DEPENSES PROGRAMME II'!M32 -> 0 | P32: ='DEPENSES PROGRAMME III'!M32 -> 0
D33: 6113 | E33: Consomptibles informatiques | F33: ='DEPENSES PROGRAMME I'!K33 -> 0 | G33: ='DEPENSES PROGRAMME II'!K33 -> 0 | H33: ='DEPENSES PROGRAMME III'!K33 -> 0 | J33: ='DEPENSES PROGRAMME I'!L33 -> 0 | K33: ='DEPENSES PROGRAMME II'!L33 -> 0 | L33: ='DEPENSES PROGRAMME III'!L33 -> 0 | N33: ='DEPENSES PROGRAMME I'!M33 -> 0 | O33: ='DEPENSES PROGRAMME II'!M33 -> 0 | P33: ='DEPENSES PROGRAMME III'!M33 -> 0
D34: 6114 | E34: Produits, petits matériels et menues dépenses d'entretien | F34: ='DEPENSES PROGRAMME I'!K34 -> 0 | G34: ='DEPENSES PROGRAMME II'!K34 -> 0 | H34: ='DEPENSES PROGRAMME III'!K34 -> 0 | J34: ='DEPENSES PROGRAMME I'!L34 -> 0 | K34: ='DEPENSES PROGRAMME II'!L34 -> 0 | L34: ='DEPENSES PROGRAMME III'!L34 -> 0 | N34: ='DEPENSES PROGRAMME I'!M34 -> 0 | O34: ='DEPENSES PROGRAMME II'!M34 -> 0 | P34: ='DEPENSES PROGRAMME III'!M34 -> 0
D35: 6115 | E35: Petits outillages et fournitures d'atelier | F35: ='DEPENSES PROGRAMME I'!K35 -> 0 | G35: ='DEPENSES PROGRAMME II'!K35 -> 0 | H35: ='DEPENSES PROGRAMME III'!K35 -> 0 | J35: ='DEPENSES PROGRAMME I'!L35 -> 0 | K35: ='DEPENSES PROGRAMME II'!L35 -> 0 | L35: ='DEPENSES PROGRAMME III'!L35 -> 0 | N35: ='DEPENSES PROGRAMME I'!M35 -> 0 | O35: ='DEPENSES PROGRAMME II'!M35 -> 0 | P35: ='DEPENSES PROGRAMME III'!M35 -> 0
D36: 6116 | E36: Instruments spécialisés | F36: ='DEPENSES PROGRAMME I'!K36 -> 0 | G36: ='DEPENSES PROGRAMME II'!K36 -> 0 | H36: ='DEPENSES PROGRAMME III'!K36 -> 0 | J36: ='DEPENSES PROGRAMME I'!L36 -> 0 | K36: ='DEPENSES PROGRAMME II'!L36 -> 0 | L36: ='DEPENSES PROGRAMME III'!L36 -> 0 | N36: ='DEPENSES PROGRAMME I'!M36 -> 0 | O36: ='DEPENSES PROGRAMME II'!M36 -> 0 | P36: ='DEPENSES PROGRAMME III'!M36 -> 0
D37: 6117 | E37: Habillement | F37: ='DEPENSES PROGRAMME I'!K37 -> 0 | G37: ='DEPENSES PROGRAMME II'!K37 -> 0 | H37: ='DEPENSES PROGRAMME III'!K37 -> 0 | J37: ='DEPENSES PROGRAMME I'!L37 -> 0 | K37: ='DEPENSES PROGRAMME II'!L37 -> 0 | L37: ='DEPENSES PROGRAMME III'!L37 -> 0 | N37: ='DEPENSES PROGRAMME I'!M37 -> 0 | O37: ='DEPENSES PROGRAMME II'!M37 -> 0 | P37: ='DEPENSES PROGRAMME III'!M37 -> 0
C38: 612 | E38: Achats de biens à usage spécifique | F38: =SUM(F39:F46) -> 0 | G38: =SUM(G39:G46) -> 0 | H38: =SUM(H39:H46) -> 0 | J38: =SUM(J39:J46) -> 0 | K38: =SUM(K39:K46) -> 0 | L38: =SUM(L39:L46) -> 0 | N38: =SUM(N39:N46) -> 0 | O38: =SUM(O39:O46) -> 0 | P38: =SUM(P39:P46) -> 0
D39: 6121 | E39: Fornitures scolaires | F39: ='DEPENSES PROGRAMME I'!K39 -> 0 | G39: ='DEPENSES PROGRAMME II'!K39 -> 0 | H39: ='DEPENSES PROGRAMME III'!K39 -> 0 | J39: ='DEPENSES PROGRAMME I'!L39 -> 0 | K39: ='DEPENSES PROGRAMME II'!L39 -> 0 | L39: ='DEPENSES PROGRAMME III'!L39 -> 0 | N39: ='DEPENSES PROGRAMME I'!M39 -> 0 | O39: ='DEPENSES PROGRAMME II'!M39 -> 0 | P39: ='DEPENSES PROGRAMME III'!M39 -> 0
D40: 6122 | E40: Consommables médicaux | F40: ='DEPENSES PROGRAMME I'!K40 -> 0 | G40: ='DEPENSES PROGRAMME II'!K40 -> 0 | H40: ='DEPENSES PROGRAMME III'!K40 -> 0 | J40: ='DEPENSES PROGRAMME I'!L40 -> 0 | K40: ='DEPENSES PROGRAMME II'!L40 -> 0 | L40: ='DEPENSES PROGRAMME III'!L40 -> 0 | N40: ='DEPENSES PROGRAMME I'!M40 -> 0 | O40: ='DEPENSES PROGRAMME II'!M40 -> 0 | P40: ='DEPENSES PROGRAMME III'!M40 -> 0
D41: 6123 | E41: Produits pahrmaceutiques | F41: ='DEPENSES PROGRAMME I'!K41 -> 0 | G41: ='DEPENSES PROGRAMME II'!K41 -> 0 | H41: ='DEPENSES PROGRAMME III'!K41 -> 0 | J41: ='DEPENSES PROGRAMME I'!L41 -> 0 | K41: ='DEPENSES PROGRAMME II'!L41 -> 0 | L41: ='DEPENSES PROGRAMME III'!L41 -> 0 | N41: ='DEPENSES PROGRAMME I'!M41 -> 0 | O41: ='DEPENSES PROGRAMME II'!M41 -> 0 | P41: ='DEPENSES PROGRAMME III'!M41 -> 0
D42: 6124 | E42: Produits vétérianaires | F42: ='DEPENSES PROGRAMME I'!K42 -> 0 | G42: ='DEPENSES PROGRAMME II'!K42 -> 0 | H42: ='DEPENSES PROGRAMME III'!K42 -> 0 | J42: ='DEPENSES PROGRAMME I'!L42 -> 0 | K42: ='DEPENSES PROGRAMME II'!L42 -> 0 | L42: ='DEPENSES PROGRAMME III'!L42 -> 0 | N42: ='DEPENSES PROGRAMME I'!M42 -> 0 | O42: ='DEPENSES PROGRAMME II'!M42 -> 0 | P42: ='DEPENSES PROGRAMME III'!M42 -> 0
D43: 6125 | E43: Produits alimentaires | F43: ='DEPENSES PROGRAMME I'!K43 -> 0 | G43: ='DEPENSES PROGRAMME II'!K43 -> 0 | H43: ='DEPENSES PROGRAMME III'!K43 -> 0 | J43: ='DEPENSES PROGRAMME I'!L43 -> 0 | K43: ='DEPENSES PROGRAMME II'!L43 -> 0 | L43: ='DEPENSES PROGRAMME III'!L43 -> 0 | N43: ='DEPENSES PROGRAMME I'!M43 -> 0 | O43: ='DEPENSES PROGRAMME II'!M43 -> 0 | P43: ='DEPENSES PROGRAMME III'!M43 -> 0
D44: 6126 | E44: Intrants agricoles | F44: ='DEPENSES PROGRAMME I'!K44 -> 0 | G44: ='DEPENSES PROGRAMME II'!K44 -> 0 | H44: ='DEPENSES PROGRAMME III'!K44 -> 0 | J44: ='DEPENSES PROGRAMME I'!L44 -> 0 | K44: ='DEPENSES PROGRAMME II'!L44 -> 0 | L44: ='DEPENSES PROGRAMME III'!L44 -> 0 | N44: ='DEPENSES PROGRAMME I'!M44 -> 0 | O44: ='DEPENSES PROGRAMME II'!M44 -> 0 | P44: ='DEPENSES PROGRAMME III'!M44 -> 0
...

Sheet RECAPITULATIF DEPENSES
B2: TABLEAU RECAPITULATIF DES DEPENSES
E4: COLLECTIVITE : …..........
B6: DEPENSES DE FONCTIONNEMENT
B7: COMPTE | E7: INTITULES | F7: MANDAT ADMIS | G7: PAIEMENT | H7: RESTE A PAYER
B8: 60 | E8: CHARGES DE PERSONNEL | F8: ='RECAP DEPENSES PAR PROGRAMME'!I10 -> 0 | G8: ='RECAP DEPENSES PAR PROGRAMME'!M10 -> 0 | H8: ='RECAP DEPENSES PAR PROGRAMME'!Q10 -> 0
B9: 61 | E9: ACHATS DE BIENS | F9: ='RECAP DEPENSES PAR PROGRAMME'!I29 -> 0 | G9: ='RECAP DEPENSES PAR PROGRAMME'!M29 -> 0 | H9: ='RECAP DEPENSES PAR PROGRAMME'!Q29 -> 0
B10: 62 | E10: ACHATS DE SERVICES ET CHARGES PERMANENTES | F10: ='RECAP DEPENSES PAR PROGRAMME'!I60 -> 0 | G10: ='RECAP DEPENSES PAR PROGRAMME'!M60 -> 0 | H10: ='RECAP DEPENSES PAR PROGRAMME'!Q60 -> 0
B11: 63 | E11: DEPENSES D'INTERVENTION | F11: ='RECAP DEPENSES PAR PROGRAMME'!I112 -> 0 | G11: ='RECAP DEPENSES PAR PROGRAMME'!M112 -> 0 | H11: ='RECAP DEPENSES PAR PROGRAMME'!Q112 -> 0
B12: 64 | E12: IMPOTS ET TAXES | F12: ='RECAP DEPENSES PAR PROGRAMME'!I121 -> 0 | G12: ='RECAP DEPENSES PAR PROGRAMME'!M121 -> 0 | H12: ='RECAP DEPENSES PAR PROGRAMME'!Q121 -> 0
B13: 65 | E13: TRANSFERTS ET SUBVENTIONS | F13: ='RECAP DEPENSES PAR PROGRAMME'!I132 -> 0 | G13: ='RECAP DEPENSES PAR PROGRAMME'!M132 -> 0 | H13: ='RECAP DEPENSES PAR PROGRAMME'!Q132 -> 0
B14: 66 | E14: CHARGES FINANCIERES | F14: ='RECAP DEPENSES PAR PROGRAMME'!I150 -> 0 | G14: ='RECAP DEPENSES PAR PROGRAMME'!M150 -> 0 | H14: ='RECAP DEPENSES PAR PROGRAMME'!Q150 -> 0
B15: 67 | E15: CHARGES DIVERSES | F15: ='RECAP DEPENSES PAR PROGRAMME'!I165 -> 0 | G15: ='RECAP DEPENSES PAR PROGRAMME'!M165 -> 0 | H15: ='RECAP DEPENSES PAR PROGRAMME'!Q165 -> 0
E16: TOTAL DEPENSES REELLES DE FONCTIONNEMENT | F16: =F8+F9+F10+F11+F12+F13+F14+F15 -> 0 | G16: =G8+G9+G10+G11+G12+G13+G14+G15 -> 0 | H16: =H8+H9+H10+H11+H12+H13+H14+H15 -> 0
B17: 12 | E17: EXCEDENT DE FONCTIONNEMENT | F17: ='RECAP DEPENSES PAR PROGRAMME'!I188 -> 0 | G17: ='RECAP DEPENSES PAR PROGRAMME'!M188 -> 0 | H17: ='RECAP DEPENSES PAR PROGRAMME'!Q188 -> 0
E18: TOTAL DEPENSES D'ORDRE DE FONCTIONNEMENT | F18: =SUM(F17) -> 0 | G18: =SUM(G17) -> 0 | H18: =SUM(H17) -> 0
E19: SOUS-TOTAL FONCTIONNEMENT | F19: =F16+F18 -> 0 | G19: =G16+G18 -> 0 | H19: =H16+H18 -> 0
B21: DEPENSES D'INVESTISSEMENT
B22: COMPTE | E22: INTITULES | F22: MANDAT ADMIS | G22: PAIEMENT | H22: RESTE A PAYER
B23: 16 | E23: EMPRUNTS ET DETTES ASSIMILEES | F23: ='RECAP DEPENSES PAR PROGRAMME'!I195 -> 0 | G23: ='RECAP DEPENSES PAR PROGRAMME'!M195 -> 0 | H23: ='RECAP DEPENSES PAR PROGRAMME'!Q195 -> 0
B24: 20 | E24: IMMOBILISATION INCORPORELLES | F24: ='RECAP DEPENSES PAR PROGRAMME'!I209 -> 0 | G24: ='RECAP DEPENSES PAR PROGRAMME'!M209 -> 0 | H24: ='RECAP DEPENSES PAR PROGRAMME'!Q209 -> 0
B25: 21 | E25: IMMOBILISATION CORPORELLES | F25: ='RECAP DEPENSES PAR PROGRAMME'!I224 -> 0 | G25: ='RECAP DEPENSES PAR PROGRAMME'!M224 -> 0 | H25: ='RECAP DEPENSES PAR PROGRAMME'!Q224 -> 0
E26: TOTAL DEPENSES REELLES D'INVESTISSEMENT | F26: =F23+F24+F25 -> 0 | G26: =G23+G24+G25 -> 0 | H26: =H23+H24+H25 -> 0
B27: 20 | E27: IMMOBILISATION INCORPORELLES | F27: ='RECAP DEPENSES PAR PROGRAMME'!I287 -> 0 | G27: ='RECAP DEPENSES PAR PROGRAMME'!M287 -> 0 | H27: ='RECAP DEPENSES PAR PROGRAMME'!Q287 -> 0
B28: 21 | E28: IMMOBILISATION CORPORELLES | F28: ='RECAP DEPENSES PAR PROGRAMME'!I288 -> 0 | G28: ='RECAP DEPENSES PAR PROGRAMME'!M288 -> 0 | H28: ='RECAP DEPENSES PAR PROGRAMME'!Q288 -> 0
E29: TOTAL DEPENSES D'ORDRE D'INVESTISSEMENT | F29: =SUM(F27:F28) -> 0 | G29: =SUM(G27:G28) -> 0 | H29: =SUM(H27:H28) -> 0
E30: SOUS-TOTAL INVESTISSEMENT | F30: =F26+F29 -> 0 | G30: =G26+G29 -> 0 | H30: =H26+H29 -> 0

Sheet EQUILIBRE
B2: TABLEAU D'EQUILIBRE DU COMPTE ADMINISTRATIF
C4: COLLECTIVITE : …..........
C6: DEPENSES | H6: RECETTES
B7: COMPTE | C7: INTITULES | D7: MANDAT ADMIS | E7: PAIEMENT | F7: RESTE A PAYER | G7: COMPTE | H7: INTITULES | I7: OR ADMIS | J7: RECOUVREMENT | K7: RESTE A RECOUVRER
B8: 60 | C8: CHARGES DE PERSONNEL | D8: ='RECAPITULATIF DEPENSES'!F8 -> 0 | E8: ='RECAPITULATIF DEPENSES'!G8 -> 0 | F8: =D8-E8 -> 0 | G8: 70 | H8: IMPOTS SUR LES REVENUS, BENEFICES ET GAINS | I8: ='RECAPITULATIF RECETTES'!G8 -> 0 | J8: ='RECAPITULATIF RECETTES'!H8 -> 0 | K8: ='RECAPITULATIF RECETTES'!I8 -> 0
B9: 61 | C9: ACHATS DE BIENS | D9: ='RECAPITULATIF DEPENSES'!F9 -> 0 | E9: ='RECAPITULATIF DEPENSES'!G9 -> 0 | F9: =D9-E9 -> 0 | G9: 71 | H9: IMPOTS SUR LE PATRIMOINE | I9: ='RECAPITULATIF RECETTES'!G9 -> 0 | J9: ='RECAPITULATIF RECETTES'!H9 -> 0 | K9: ='RECAPITULATIF RECETTES'!I9 -> 0
B10: 62 | C10: ACHATS DE SERVICES ET CHARGES PERMANENTES | D10: ='RECAPITULATIF DEPENSES'!F10 -> 0 | E10: ='RECAPITULATIF DEPENSES'!G10 -> 0 | F10: =D10-E10 -> 0 | G10: 72 | H10: IMPOTS SUR LES BIENS ET SERVICES | I10: ='RECAPITULATIF RECETTES'!G10 -> 0 | J10: ='RECAPITULATIF RECETTES'!H10 -> 0 | K10: ='RECAPITULATIF RECETTES'!I10 -> 0
B11: 63 | C11: DEPENSES D'INTERVENTION | D11: ='RECAPITULATIF DEPENSES'!F11 -> 0 | E11: ='RECAPITULATIF DEPENSES'!G11 -> 0 | F11: =D11-E11 -> 0 | G11: 74 | H11: AUTRES RECETTES FISCALES | I11: ='RECAPITULATIF RECETTES'!G11 -> 0 | J11: ='RECAPITULATIF RECETTES'!H11 -> 0 | K11: ='RECAPITULATIF RECETTES'!I11 -> 0
B12: 64 | C12: IMPOTS ET TAXES | D12: ='RECAPITULATIF DEPENSES'!F12 -> 0 | E12: ='RECAPITULATIF DEPENSES'!G12 -> 0 | F12: =D12-E12 -> 0 | G12: 75 | H12: CONTRIBUTIONS RECUES DES TIERS | I12: ='RECAPITULATIF RECETTES'!G12 -> 0 | J12: ='RECAPITULATIF RECETTES'!H12 -> 0 | K12: ='RECAPITULATIF RECETTES'!I12 -> 0
B13: 65 | C13: TRANSFERTS ET SUBVENTIONS | D13: ='RECAPITULATIF DEPENSES'!F13 -> 0 | E13: ='RECAPITULATIF DEPENSES'!G13 -> 0 | F13: =D13-E13 -> 0 | G13: 76 | H13: PRODUITS FINANCIERS | I13: ='RECAPITULATIF RECETTES'!G13 -> 0 | J13: ='RECAPITULATIF RECETTES'!H13 -> 0 | K13: ='RECAPITULATIF RECETTES'!I13 -> 0
B14: 66 | C14: CHARGES FINANCIERES | D14: ='RECAPITULATIF DEPENSES'!F14 -> 0 | E14: ='RECAPITULATIF DEPENSES'!G14 -> 0 | F14: =D14-E14 -> 0 | G14: 77 | H14: RECETTES NON FISCALES | I14: ='RECAPITULATIF RECETTES'!G14 -> 0 | J14: ='RECAPITULATIF RECETTES'!H14 -> 0 | K14: ='RECAPITULATIF RECETTES'!I14 -> 0
B15: 67 | C15: CHARGES DIVERSES | D15: ='RECAPITULATIF DEPENSES'!F15 -> 0 | E15: ='RECAPITULATIF DEPENSES'!G15 -> 0 | F15: =D15-E15 -> 0
B16: 119 | C16: REPORT A NOUVEAU (DEFICIT) | F16: =D16-E16 -> 0 | G16: 110 | H16: REPORT A NOUVEAU (EXCEDENT) | K16: ='RECAPITULATIF RECETTES'!I16 -> 0
C17: TOTAL DEPENSES REELLES DE FONCTIONNEMENT | D17: =+D8+D9+D10+D11+D12+D13+D14+D15+D16 -> 0 | E17: =+E8+E9+E10+E11+E12+E13+E14+E15+E16 -> 0 | F17: =+F8+F9+F10+F11+F12+F13+F14+F15+F16 -> 0 | H17: TOTAL DEPENSES REELLES DE FONCTIONNEMENT | I17: =+I8+I9+I10+I11+I12+I13++I14+I16 -> 0 | J17: =+J8+J9+J10+J11+J12+J13++J14+J16 -> 0 | K17: =+K8+K9+K10+K11+K12+K13++K14+K16 -> 0
B18: 12 | C18: EXCEDENT DE FONCTIONNEMENT | G18: 774 | H18: PRODUCTION IMMOBILISEE
C19: TOTAL DEPENSES D'ORDRE DE FONCTIONNEMENT | D19: =+D18 -> 0 | E19: =+E18 -> 0 | F19: =+F18 -> 0 | H19: TOTAL DEPENSES D'ORDRE DE FONCTIONNEMENT | I19: =+I18 -> 0 | J19: =+J18 -> 0 | K19: =+K18 -> 0
C20: TOTAL DEPENSES DE FONCTIONNEMENT (2) | D20: =+D17+D19 -> 0 | H20: TOTAL RECETTES DE FONCTIONNEMENT (1) | I20: =+I17+I19 -> 0
C21: EXCEDENT DE FONCTIONNEMENT (1) - (2) | D21: =+I20-D20 -> 0 | H21: DEFICIT DE FONCTIONNEMENT (1) - (2)
C23: SECTION INVESTISSEMENT | H23: SECTION INVESTISSEMENT
B24: COMPTE | C24: INTITULE | D24: MANDAT ADMIS | E24: PAIEMENT | F24: RESTE A PAYER | G24: COMPTE | H24: INTITULE | I24: OR ADMIS | J24: RECOUVREMENT | K24: RESTE A RECOUVRER
B25: 16 | C25: EMPRUNTS ET DETTES ASSIMILEES | D25: ='RECAPITULATIF DEPENSES'!F23 -> 0 | E25: ='RECAPITULATIF DEPENSES'!G23 -> 0 | F25: =+D25-E25 -> 0 | G25: 10 | H25: FONDS, DOTATIONS ET RESERVES | I25: ='RECAPITULATIF RECETTES'!G21 -> 0 | J25: ='RECAPITULATIF RECETTES'!H21 -> 0 | K25: ='RECAPITULATIF RECETTES'!I21 -> 0
B26: 20 | C26: IMMOBILISATION INCORPORELLES | D26: ='RECAPITULATIF DEPENSES'!F24 -> 0 | E26: ='RECAPITULATIF DEPENSES'!G24 -> 0 | F26: =+D26-E26 -> 0 | G26: 13 | H26: SUBVENTIONS D'EQUIPEMENT | I26: ='RECAPITULATIF RECETTES'!G22 -> 0 | J26: ='RECAPITULATIF RECETTES'!H22 -> 0 | K26: ='RECAPITULATIF RECETTES'!I22 -> 0
B27: 21 | C27: IMMOBILISATION CORPORELLES | D27: ='RECAPITULATIF DEPENSES'!F25 -> 0 | E27: ='RECAPITULATIF DEPENSES'!G25 -> 0 | F27: =+D27-E27 -> 0 | G27: 14 | H27: CESSIONS D'IMMOBILISATIONS | I27: ='RECAPITULATIF RECETTES'!G23 -> 0 | J27: ='RECAPITULATIF RECETTES'!H23 -> 0 | K27: ='RECAPITULATIF RECETTES'!I23 -> 0
G28: 16 | H28: EMPRUNTS ET DETTES ASSIMILEES | I28: ='RECAPITULATIF RECETTES'!G24 -> 0 | J28: ='RECAPITULATIF RECETTES'!H24 -> 0 | K28: ='RECAPITULATIF RECETTES'!I24 -> 0
B29: 119 | C29: REPORT A NOUVEAU (DEFICIT) | F29: =+D29-E29 -> 0 | G29: 110 | H29: REPORT A NOUVEAU (EXCEDENT)
C30: TOTAL DEPENSES REELLES D'INVESTISSEMENT | D30: =D25+D26+D27+D29 -> 0 | E30: =E25+E26+E27+E29 -> 0 | F30: =F25+F26+F27+F29 -> 0 | H30: TOTAL DEPENSES REELLES D'INVESTISSEMENT | I30: =+I25+I26+I27+I28+I29 -> 0 | J30: =+J25+J26+J27+J28+J29 -> 0 | K30: =+K25+K26+K27+K28+K29 -> 0
B31: 20 | C31: IMMOBILISATION INCORPORELLES | D31: =+'RECAPITULATIF DEPENSES'!F27 -> 0 | E31: =+'RECAPITULATIF DEPENSES'!G27 -> 0 | F31: =D31-E31 -> 0 | G31: 1012 | H31: DOTATION DE L'ETAT | I31: ='RECAPITULATIF RECETTES'!G26 -> 0 | J31: ='RECAPITULATIF RECETTES'!H26 -> 0 | K31: ='RECAPITULATIF RECETTES'!I26 -> 0
B32: 21 | C32: IMMOBILISATION CORPORELLES | D32: =+'RECAPITULATIF DEPENSES'!F28 -> 0 | E32: =+'RECAPITULATIF DEPENSES'!G28 -> 0 | F32: =D32-E32 -> 0 | G32: 1064 | H32: EXCEDENT DE FONCTIONNEMENT CAPITALISE
C33: TOTAL DEPENSES D'ORDRE D'INVESTISSEMENT | D33: =D31+D32 -> 0 | E33: =E31+E32 -> 0 | F33: =F31+F32 -> 0 | H33: TOTAL DEPENSES D'ORDRE D'INVESTISSEMENT | I33: =I31+I32 -> 0 | J33: =J31+J32 -> 0 | K33: =K31+K32 -> 0
C34: TOTAL DEPENSES D'INVESTISSEMENT (4) | D34: =D30+D33 -> 0 | E34: =E30+E33 -> 0 | F34: =F30+F33 -> 0 | H34: TOTAL RECETTES D'INVESTISSEMENT (3) | I34: =+I30+I33 -> 0 | J34: =+J30+J33 -> 0 | K34: =+K30+K33 -> 0
C35: EXCEDENT D'INVESTISSEMENT (3) - (4) | D35: =I34-D34 -> 0 | H35: DEFICIT D'INVESTISSEMENT (3) - (4)
